Workbook

Sheet Summary
A1: Phase | B1: Cases | C1: Run | D1: PASS | E1: FAIL | F1: BLOCKED | G1: Not run | H1: % Run | I1: % Pass | J1: P1 cases | K1: P1 FAIL | L1: GATE
A2: Phase 01 Foundation & Access | B2: 177 | C2: =COUNTIF('Phase 01 Foundation & Access'!$G$2:$G$178,"PASS")+COUNTIF('Phase 01 Foundation & Access'!$G$2:$G$178,"FAIL")+COUNTIF('Phase 01 Foundation & Access'!$G$2:$G$178,"BLOCKED") | D2: =COUNTIF('Phase 01 Foundation & Access'!$G$2:$G$178,"PASS") | E2: =COUNTIF('Phase 01 Foundation & Access'!$G$2:$G$178,"FAIL") | F2: =COUNTIF('Phase 01 Foundation & Access'!$G$2:$G$178,"BLOCKED") | G2: =177-(COUNTIF('Phase 01 Foundation & Access'!$G$2:$G$178,"PASS")+COUNTIF('Phase 01 Foundation & Access'!$G$2:$G$178,"FAIL")+COUNTIF('Phase 01 Foundation & Access'!$G$2:$G$178,"BLOCKED")) | H2: =IF(177=0,0,(COUNTIF('Phase 01 Foundation & Access'!$G$2:$G$178,"PASS")+COUNTIF('Phase 01 Foundation & Access'!$G$2:$G$178,"FAIL")+COUNTIF('Phase 01 Foundation & Access'!$G$2:$G$178,"BLOCKED"))/177) | I2: =IF((COUNTIF('Phase 01 Foundation & Access'!$G$2:$G$178,"PASS")+COUNTIF('Phase 01 Foundation & Access'!$G$2:$G$178,"FAIL")+COUNTIF('Phase 01 Foundation & Access'!$G$2:$G$178,"BLOCKED"))=0,0,COUNTIF('Phase 01 Foundation & Access'!$G$2:$G$178,"PASS")/(COUNTIF('Phase 01 Foundation & Access'!$G$2:$G$178,"PASS")+COUNTIF('Phase 01 Foundation & Access'!$G$2:$G$178,"FAIL")+COUNTIF('Phase 01 Foundation & Access'!$G$2:$G$178,"BLOCKED"))) | J2: =COUNTIF('Phase 01 Foundation & Access'!$C$2:$C$178,"P1") | K2: =COUNTIFS('Phase 01 Foundation & Access'!$C$2:$C$178,"P1",'Phase 01 Foundation & Access'!$G$2:$G$178,"FAIL") | L2: =IF(COUNTIFS('Phase 01 Foundation & Access'!$C$2:$C$178,"P1",'Phase 01 Foundation & Access'!$G$2:$G$178,"FAIL")>0,"BLOCKED - open P1",IF((COUNTIF('Phase 01 Foundation & Access'!$G$2:$G$178,"PASS")+COUNTIF('Phase 01 Foundation & Access'!$G$2:$G$178,"FAIL")+COUNTIF('Phase 01 Foundation & Access'!$G$2:$G$178,"BLOCKED"))<177,"IN PROGRESS",IF(COUNTIF('Phase 01 Foundation & Access'!$G$2:$G$178,"FAIL")>0,"BLOCKED - open defects","PASSED")))
A3: Phase 02 Settings & Masters | B3: 1056 | C3: =COUNTIF('Phase 02 Settings & Masters'!$G$2:$G$1057,"PASS")+COUNTIF('Phase 02 Settings & Masters'!$G$2:$G$1057,"FAIL")+COUNTIF('Phase 02 Settings & Masters'!$G$2:$G$1057,"BLOCKED") | D3: =COUNTIF('Phase 02 Settings & Masters'!$G$2:$G$1057,"PASS") | E3: =COUNTIF('Phase 02 Settings & Masters'!$G$2:$G$1057,"FAIL") | F3: =COUNTIF('Phase 02 Settings & Masters'!$G$2:$G$1057,"BLOCKED") | G3: =1056-(COUNTIF('Phase 02 Settings & Masters'!$G$2:$G$1057,"PASS")+COUNTIF('Phase 02 Settings & Masters'!$G$2:$G$1057,"FAIL")+COUNTIF('Phase 02 Settings & Masters'!$G$2:$G$1057,"BLOCKED")) | H3: =IF(1056=0,0,(COUNTIF('Phase 02 Settings & Masters'!$G$2:$G$1057,"PASS")+COUNTIF('Phase 02 Settings & Masters'!$G$2:$G$1057,"FAIL")+COUNTIF('Phase 02 Settings & Masters'!$G$2:$G$1057,"BLOCKED"))/1056) | I3: =IF((COUNTIF('Phase 02 Settings & Masters'!$G$2:$G$1057,"PASS")+COUNTIF('Phase 02 Settings & Masters'!$G$2:$G$1057,"FAIL")+COUNTIF('Phase 02 Settings & Masters'!$G$2:$G$1057,"BLOCKED"))=0,0,COUNTIF('Phase 02 Settings & Masters'!$G$2:$G$1057,"PASS")/(COUNTIF('Phase 02 Settings & Masters'!$G$2:$G$1057,"PASS")+COUNTIF('Phase 02 Settings & Masters'!$G$2:$G$1057,"FAIL")+COUNTIF('Phase 02 Settings & Masters'!$G$2:$G$1057,"BLOCKED"))) | J3: =COUNTIF('Phase 02 Settings & Masters'!$C$2:$C$1057,"P1") | K3: =COUNTIFS('Phase 02 Settings & Masters'!$C$2:$C$1057,"P1",'Phase 02 Settings & Masters'!$G$2:$G$1057,"FAIL") | L3: =IF(COUNTIFS('Phase 02 Settings & Masters'!$C$2:$C$1057,"P1",'Phase 02 Settings & Masters'!$G$2:$G$1057,"FAIL")>0,"BLOCKED - open P1",IF((COUNTIF('Phase 02 Settings & Masters'!$G$2:$G$1057,"PASS")+COUNTIF('Phase 02 Settings & Masters'!$G$2:$G$1057,"FAIL")+COUNTIF('Phase 02 Settings & Masters'!$G$2:$G$1057,"BLOCKED"))<1056,"IN PROGRESS",IF(COUNTIF('Phase 02 Settings & Masters'!$G$2:$G$1057,"FAIL")>0,"BLOCKED - open defects","PASSED")))
A4: Phase 03 Patient & Records | B4: 100 | C4: =COUNTIF('Phase 03 Patient & Records'!$G$2:$G$101,"PASS")+COUNTIF('Phase 03 Patient & Records'!$G$2:$G$101,"FAIL")+COUNTIF('Phase 03 Patient & Records'!$G$2:$G$101,"BLOCKED") | D4: =COUNTIF('Phase 03 Patient & Records'!$G$2:$G$101,"PASS") | E4: =COUNTIF('Phase 03 Patient & Records'!$G$2:$G$101,"FAIL") | F4: =COUNTIF('Phase 03 Patient & Records'!$G$2:$G$101,"BLOCKED") | G4: =100-(COUNTIF('Phase 03 Patient & Records'!$G$2:$G$101,"PASS")+COUNTIF('Phase 03 Patient & Records'!$G$2:$G$101,"FAIL")+COUNTIF('Phase 03 Patient & Records'!$G$2:$G$101,"BLOCKED")) | H4: =IF(100=0,0,(COUNTIF('Phase 03 Patient & Records'!$G$2:$G$101,"PASS")+COUNTIF('Phase 03 Patient & Records'!$G$2:$G$101,"FAIL")+COUNTIF('Phase 03 Patient & Records'!$G$2:$G$101,"BLOCKED"))/100) | I4: =IF((COUNTIF('Phase 03 Patient & Records'!$G$2:$G$101,"PASS")+COUNTIF('Phase 03 Patient & Records'!$G$2:$G$101,"FAIL")+COUNTIF('Phase 03 Patient & Records'!$G$2:$G$101,"BLOCKED"))=0,0,COUNTIF('Phase 03 Patient & Records'!$G$2:$G$101,"PASS")/(COUNTIF('Phase 03 Patient & Records'!$G$2:$G$101,"PASS")+COUNTIF('Phase 03 Patient & Records'!$G$2:$G$101,"FAIL")+COUNTIF('Phase 03 Patient & Records'!$G$2:$G$101,"BLOCKED"))) | J4: =COUNTIF('Phase 03 Patient & Records'!$C$2:$C$101,"P1") | K4: =COUNTIFS('Phase 03 Patient & Records'!$C$2:$C$101,"P1",'Phase 03 Patient & Records'!$G$2:$G$101,"FAIL") | L4: =IF(COUNTIFS('Phase 03 Patient & Records'!$C$2:$C$101,"P1",'Phase 03 Patient & Records'!$G$2:$G$101,"FAIL")>0,"BLOCKED - open P1",IF((COUNTIF('Phase 03 Patient & Records'!$G$2:$G$101,"PASS")+COUNTIF('Phase 03 Patient & Records'!$G$2:$G$101,"FAIL")+COUNTIF('Phase 03 Patient & Records'!$G$2:$G$101,"BLOCKED"))<100,"IN PROGRESS",IF(COUNTIF('Phase 03 Patient & Records'!$G$2:$G$101,"FAIL")>0,"BLOCKED - open defects","PASSED")))
A5: Phase 04 OPD Journey | B5: 260 | C5: =COUNTIF('Phase 04 OPD Journey'!$G$2:$G$261,"PASS")+COUNTIF('Phase 04 OPD Journey'!$G$2:$G$261,"FAIL")+COUNTIF('Phase 04 OPD Journey'!$G$2:$G$261,"BLOCKED") | D5: =COUNTIF('Phase 04 OPD Journey'!$G$2:$G$261,"PASS") | E5: =COUNTIF('Phase 04 OPD Journey'!$G$2:$G$261,"FAIL") | F5: =COUNTIF('Phase 04 OPD Journey'!$G$2:$G$261,"BLOCKED") | G5: =260-(COUNTIF('Phase 04 OPD Journey'!$G$2:$G$261,"PASS")+COUNTIF('Phase 04 OPD Journey'!$G$2:$G$261,"FAIL")+COUNTIF('Phase 04 OPD Journey'!$G$2:$G$261,"BLOCKED")) | H5: =IF(260=0,0,(COUNTIF('Phase 04 OPD Journey'!$G$2:$G$261,"PASS")+COUNTIF('Phase 04 OPD Journey'!$G$2:$G$261,"FAIL")+COUNTIF('Phase 04 OPD Journey'!$G$2:$G$261,"BLOCKED"))/260) | I5: =IF((COUNTIF('Phase 04 OPD Journey'!$G$2:$G$261,"PASS")+COUNTIF('Phase 04 OPD Journey'!$G$2:$G$261,"FAIL")+COUNTIF('Phase 04 OPD Journey'!$G$2:$G$261,"BLOCKED"))=0,0,COUNTIF('Phase 04 OPD Journey'!$G$2:$G$261,"PASS")/(COUNTIF('Phase 04 OPD Journey'!$G$2:$G$261,"PASS")+COUNTIF('Phase 04 OPD Journey'!$G$2:$G$261,"FAIL")+COUNTIF('Phase 04 OPD Journey'!$G$2:$G$261,"BLOCKED"))) | J5: =COUNTIF('Phase 04 OPD Journey'!$C$2:$C$261,"P1") | K5: =COUNTIFS('Phase 04 OPD Journey'!$C$2:$C$261,"P1",'Phase 04 OPD Journey'!$G$2:$G$261,"FAIL") | L5: =IF(COUNTIFS('Phase 04 OPD Journey'!$C$2:$C$261,"P1",'Phase 04 OPD Journey'!$G$2:$G$261,"FAIL")>0,"BLOCKED - open P1",IF((COUNTIF('Phase 04 OPD Journey'!$G$2:$G$261,"PASS")+COUNTIF('Phase 04 OPD Journey'!$G$2:$G$261,"FAIL")+COUNTIF('Phase 04 OPD Journey'!$G$2:$G$261,"BLOCKED"))<260,"IN PROGRESS",IF(COUNTIF('Phase 04 OPD Journey'!$G$2:$G$261,"FAIL")>0,"BLOCKED - open defects","PASSED")))
A6: Phase 05 Lab & Radiology | B6: 24 | C6: =COUNTIF('Phase 05 Lab & Radiology'!$G$2:$G$25,"PASS")+COUNTIF('Phase 05 Lab & Radiology'!$G$2:$G$25,"FAIL")+COUNTIF('Phase 05 Lab & Radiology'!$G$2:$G$25,"BLOCKED") | D6: =COUNTIF('Phase 05 Lab & Radiology'!$G$2:$G$25,"PASS") | E6: =COUNTIF('Phase 05 Lab & Radiology'!$G$2:$G$25,"FAIL") | F6: =COUNTIF('Phase 05 Lab & Radiology'!$G$2:$G$25,"BLOCKED") | G6: =24-(COUNTIF('Phase 05 Lab & Radiology'!$G$2:$G$25,"PASS")+COUNTIF('Phase 05 Lab & Radiology'!$G$2:$G$25,"FAIL")+COUNTIF('Phase 05 Lab & Radiology'!$G$2:$G$25,"BLOCKED")) | H6: =IF(24=0,0,(COUNTIF('Phase 05 Lab & Radiology'!$G$2:$G$25,"PASS")+COUNTIF('Phase 05 Lab & Radiology'!$G$2:$G$25,"FAIL")+COUNTIF('Phase 05 Lab & Radiology'!$G$2:$G$25,"BLOCKED"))/24) | I6: =IF((COUNTIF('Phase 05 Lab & Radiology'!$G$2:$G$25,"PASS")+COUNTIF('Phase 05 Lab & Radiology'!$G$2:$G$25,"FAIL")+COUNTIF('Phase 05 Lab & Radiology'!$G$2:$G$25,"BLOCKED"))=0,0,COUNTIF('Phase 05 Lab & Radiology'!$G$2:$G$25,"PASS")/(COUNTIF('Phase 05 Lab & Radiology'!$G$2:$G$25,"PASS")+COUNTIF('Phase 05 Lab & Radiology'!$G$2:$G$25,"FAIL")+COUNTIF('Phase 05 Lab & Radiology'!$G$2:$G$25,"BLOCKED"))) | J6: =COUNTIF('Phase 05 Lab & Radiology'!$C$2:$C$25,"P1") | K6: =COUNTIFS('Phase 05 Lab & Radiology'!$C$2:$C$25,"P1",'Phase 05 Lab & Radiology'!$G$2:$G$25,"FAIL") | L6: =IF(COUNTIFS('Phase 05 Lab & Radiology'!$C$2:$C$25,"P1",'Phase 05 Lab & Radiology'!$G$2:$G$25,"FAIL")>0,"BLOCKED - open P1",IF((COUNTIF('Phase 05 Lab & Radiology'!$G$2:$G$25,"PASS")+COUNTIF('Phase 05 Lab & Radiology'!$G$2:$G$25,"FAIL")+COUNTIF('Phase 05 Lab & Radiology'!$G$2:$G$25,"BLOCKED"))<24,"IN PROGRESS",IF(COUNTIF('Phase 05 Lab & Radiology'!$G$2:$G$25,"FAIL")>0,"BLOCKED - open defects","PASSED")))
A8: TOTAL | B8: =SUM(B2:B6) | C8: =SUM(C2:C6) | D8: =SUM(D2:D6) | E8: =SUM(E2:E6) | F8: =SUM(F2:F6) | G8: =SUM(G2:G6) | H8: =IF(B8=0,0,C8/B8) | I8: =IF(C8=0,0,D8/C8) | J8: =SUM(J2:J6) | K8: =SUM(K2:K6) | L8: =IF(K8>0,"NOT READY - open P1","")
A10: A phase is DONE only when: every case has a Status, zero open P1 defects, and every P1 case has a passing Playwright spec.

Sheet Scenario Status
A1: Journey Scenario | B1: Phase | C1: Cases | D1: PASS | E1: FAIL | F1: Not run | G1: Scenario Verdict
A2: P1-Setup | B2: Phase 01 Foundation & Access | C2: =COUNTIF('Phase 01 Foundation & Access'!$O$2:$O$178,"P1-Setup") | D2: =COUNTIFS('Phase 01 Foundation & Access'!$O$2:$O$178,"P1-Setup",'Phase 01 Foundation & Access'!$G$2:$G$178,"PASS") | E2: =COUNTIFS('Phase 01 Foundation & Access'!$O$2:$O$178,"P1-Setup",'Phase 01 Foundation & Access'!$G$2:$G$178,"FAIL") | F2: =COUNTIF('Phase 01 Foundation & Access'!$O$2:$O$178,"P1-Setup")-COUNTIFS('Phase 01 Foundation & Access'!$O$2:$O$178,"P1-Setup",'Phase 01 Foundation & Access'!$G$2:$G$178,"PASS")-COUNTIFS('Phase 01 Foundation & Access'!$O$2:$O$178,"P1-Setup",'Phase 01 Foundation & Access'!$G$2:$G$178,"FAIL")-COUNTIFS('Phase 01 Foundation & Access'!$O$2:$O$178,"P1-Setup",'Phase 01 Foundation & Access'!$G$2:$G$178,"BLOCKED") | G2: =IF(COUNTIFS('Phase 01 Foundation & Access'!$O$2:$O$178,"P1-Setup",'Phase 01 Foundation & Access'!$G$2:$G$178,"FAIL")>0,"FAIL",IF(COUNTIFS('Phase 01 Foundation & Access'!$O$2:$O$178,"P1-Setup",'Phase 01 Foundation & Access'!$G$2:$G$178,"PASS")=COUNTIF('Phase 01 Foundation & Access'!$O$2:$O$178,"P1-Setup"),"PASS",IF(COUNTIFS('Phase 01 Foundation & Access'!$O$2:$O$178,"P1-Setup",'Phase 01 Foundation & Access'!$G$2:$G$178,"PASS")+COUNTIFS('Phase 01 Foundation & Access'!$O$2:$O$178,"P1-Setup",'Phase 01 Foundation & Access'!$G$2:$G$178,"BLOCKED")>0,"IN PROGRESS","NOT STARTED")))
A3: P2-Setup | B3: Phase 02 Settings & Masters | C3: =COUNTIF('Phase 02 Settings & Masters'!$O$2:$O$1057,"P2-Setup") | D3: =COUNTIFS('Phase 02 Settings & Masters'!$O$2:$O$1057,"P2-Setup",'Phase 02 Settings & Masters'!$G$2:$G$1057,"PASS") | E3: =COUNTIFS('Phase 02 Settings & Masters'!$O$2:$O$1057,"P2-Setup",'Phase 02 Settings & Masters'!$G$2:$G$1057,"FAIL") | F3: =COUNTIF('Phase 02 Settings & Masters'!$O$2:$O$1057,"P2-Setup")-COUNTIFS('Phase 02 Settings & Masters'!$O$2:$O$1057,"P2-Setup",'Phase 02 Settings & Masters'!$G$2:$G$1057,"PASS")-COUNTIFS('Phase 02 Settings & Masters'!$O$2:$O$1057,"P2-Setup",'Phase 02 Settings & Masters'!$G$2:$G$1057,"FAIL")-COUNTIFS('Phase 02 Settings & Masters'!$O$2:$O$1057,"P2-Setup",'Phase 02 Settings & Masters'!$G$2:$G$1057,"BLOCKED") | G3: =IF(COUNTIFS('Phase 02 Settings & Masters'!$O$2:$O$1057,"P2-Setup",'Phase 02 Settings & Masters'!$G$2:$G$1057,"FAIL")>0,"FAIL",IF(COUNTIFS('Phase 02 Settings & Masters'!$O$2:$O$1057,"P2-Setup",'Phase 02 Settings & Masters'!$G$2:$G$1057,"PASS")=COUNTIF('Phase 02 Settings & Masters'!$O$2:$O$1057,"P2-Setup"),"PASS",IF(COUNTIFS('Phase 02 Settings & Masters'!$O$2:$O$1057,"P2-Setup",'Phase 02 Settings & Masters'!$G$2:$G$1057,"PASS")+COUNTIFS('Phase 02 Settings & Masters'!$O$2:$O$1057,"P2-Setup",'Phase 02 Settings & Masters'!$G$2:$G$1057,"BLOCKED")>0,"IN PROGRESS","NOT STARTED")))
A4: P3-S01 | B4: Phase 03 Patient & Records | C4: =COUNTIF('Phase 03 Patient & Records'!$O$2:$O$101,"P3-S01") | D4: =COUNTIFS('Phase 03 Patient & Records'!$O$2:$O$101,"P3-S01",'Phase 03 Patient & Records'!$G$2:$G$101,"PASS") | E4: =COUNTIFS('Phase 03 Patient & Records'!$O$2:$O$101,"P3-S01",'Phase 03 Patient & Records'!$G$2:$G$101,"FAIL") | F4: =COUNTIF('Phase 03 Patient & Records'!$O$2:$O$101,"P3-S01")-COUNTIFS('Phase 03 Patient & Records'!$O$2:$O$101,"P3-S01",'Phase 03 Patient & Records'!$G$2:$G$101,"PASS")-COUNTIFS('Phase 03 Patient & Records'!$O$2:$O$101,"P3-S01",'Phase 03 Patient & Records'!$G$2:$G$101,"FAIL")-COUNTIFS('Phase 03 Patient & Records'!$O$2:$O$101,"P3-S01",'Phase 03 Patient & Records'!$G$2:$G$101,"BLOCKED") | G4: =IF(COUNTIFS('Phase 03 Patient & Records'!$O$2:$O$101,"P3-S01",'Phase 03 Patient & Records'!$G$2:$G$101,"FAIL")>0,"FAIL",IF(COUNTIFS('Phase 03 Patient & Records'!$O$2:$O$101,"P3-S01",'Phase 03 Patient & Records'!$G$2:$G$101,"PASS")=COUNTIF('Phase 03 Patient & Records'!$O$2:$O$101,"P3-S01"),"PASS",IF(COUNTIFS('Phase 03 Patient & Records'!$O$2:$O$101,"P3-S01",'Phase 03 Patient & Records'!$G$2:$G$101,"PASS")+COUNTIFS('Phase 03 Patient & Records'!$O$2:$O$101,"P3-S01",'Phase 03 Patient & Records'!$G$2:$G$101,"BLOCKED")>0,"IN PROGRESS","NOT STARTED")))
A5: P3-S02 | B5: Phase 03 Patient & Records | C5: =COUNTIF('Phase 03 Patient & Records'!$O$2:$O$101,"P3-S02") | D5: =COUNTIFS('Phase 03 Patient & Records'!$O$2:$O$101,"P3-S02",'Phase 03 Patient & Records'!$G$2:$G$101,"PASS") | E5: =COUNTIFS('Phase 03 Patient & Records'!$O$2:$O$101,"P3-S02",'Phase 03 Patient & Records'!$G$2:$G$101,"FAIL") | F5: =COUNTIF('Phase 03 Patient & Records'!$O$2:$O$101,"P3-S02")-COUNTIFS('Phase 03 Patient & Records'!$O$2:$O$101,"P3-S02",'Phase 03 Patient & Records'!$G$2:$G$101,"PASS")-COUNTIFS('Phase 03 Patient & Records'!$O$2:$O$101,"P3-S02",'Phase 03 Patient & Records'!$G$2:$G$101,"FAIL")-COUNTIFS('Phase 03 Patient & Records'!$O$2:$O$101,"P3-S02",'Phase 03 Patient & Records'!$G$2:$G$101,"BLOCKED") | G5: =IF(COUNTIFS('Phase 03 Patient & Records'!$O$2:$O$101,"P3-S02",'Phase 03 Patient & Records'!$G$2:$G$101,"FAIL")>0,"FAIL",IF(COUNTIFS('Phase 03 Patient & Records'!$O$2:$O$101,"P3-S02",'Phase 03 Patient & Records'!$G$2:$G$101,"PASS")=COUNTIF('Phase 03 Patient & Records'!$O$2:$O$101,"P3-S02"),"PASS",IF(COUNTIFS('Phase 03 Patient & Records'!$O$2:$O$101,"P3-S02",'Phase 03 Patient & Records'!$G$2:$G$101,"PASS")+COUNTIFS('Phase 03 Patient & Records'!$O$2:$O$101,"P3-S02",'Phase 03 Patient & Records'!$G$2:$G$101,"BLOCKED")>0,"IN PROGRESS","NOT STARTED")))
A6: P3-S03 | B6: Phase 03 Patient & Records | C6: =COUNTIF('Phase 03 Patient & Records'!$O$2:$O$101,"P3-S03") | D6: =COUNTIFS('Phase 03 Patient & Records'!$O$2:$O$101,"P3-S03",'Phase 03 Patient & Records'!$G$2:$G$101,"PASS") | E6: =COUNTIFS('Phase 03 Patient & Records'!$O$2:$O$101,"P3-S03",'Phase 03 Patient & Records'!$G$2:$G$101,"FAIL") | F6: =COUNTIF('Phase 03 Patient & Records'!$O$2:$O$101,"P3-S03")-COUNTIFS('Phase 03 Patient & Records'!$O$2:$O$101,"P3-S03",'Phase 03 Patient & Records'!$G$2:$G$101,"PASS")-COUNTIFS('Phase 03 Patient & Records'!$O$2:$O$101,"P3-S03",'Phase 03 Patient & Records'!$G$2:$G$101,"FAIL")-COUNTIFS('Phase 03 Patient & Records'!$O$2:$O$101,"P3-S03",'Phase 03 Patient & Records'!$G$2:$G$101,"BLOCKED") | G6: =IF(COUNTIFS('Phase 03 Patient & Records'!$O$2:$O$101,"P3-S03",'Phase 03 Patient & Records'!$G$2:$G$101,"FAIL")>0,"FAIL",IF(COUNTIFS('Phase 03 Patient & Records'!$O$2:$O$101,"P3-S03",'Phase 03 Patient & Records'!$G$2:$G$101,"PASS")=COUNTIF('Phase 03 Patient & Records'!$O$2:$O$101,"P3-S03"),"PASS",IF(COUNTIFS('Phase 03 Patient & Records'!$O$2:$O$101,"P3-S03",'Phase 03 Patient & Records'!$G$2:$G$101,"PASS")+COUNTIFS('Phase 03 Patient & Records'!$O$2:$O$101,"P3-S03",'Phase 03 Patient & Records'!$G$2:$G$101,"BLOCKED")>0,"IN PROGRESS","NOT STARTED")))
A7: P3-S04 | B7: Phase 03 Patient & Records | C7: =COUNTIF('Phase 03 Patient & Records'!$O$2:$O$101,"P3-S04") | D7: =COUNTIFS('Phase 03 Patient & Records'!$O$2:$O$101,"P3-S04",'Phase 03 Patient & Records'!$G$2:$G$101,"PASS") | E7: =COUNTIFS('Phase 03 Patient & Records'!$O$2:$O$101,"P3-S04",'Phase 03 Patient & Records'!$G$2:$G$101,"FAIL") | F7: =COUNTIF('Phase 03 Patient & Records'!$O$2:$O$101,"P3-S04")-COUNTIFS('Phase 03 Patient & Records'!$O$2:$O$101,"P3-S04",'Phase 03 Patient & Records'!$G$2:$G$101,"PASS")-COUNTIFS('Phase 03 Patient & Records'!$O$2:$O$101,"P3-S04",'Phase 03 Patient & Records'!$G$2:$G$101,"FAIL")-COUNTIFS('Phase 03 Patient & Records'!$O$2:$O$101,"P3-S04",'Phase 03 Patient & Records'!$G$2:$G$101,"BLOCKED") | G7: =IF(COUNTIFS('Phase 03 Patient & Records'!$O$2:$O$101,"P3-S04",'Phase 03 Patient & Records'!$G$2:$G$101,"FAIL")>0,"FAIL",IF(COUNTIFS('Phase 03 Patient & Records'!$O$2:$O$101,"P3-S04",'Phase 03 Patient & Records'!$G$2:$G$101,"PASS")=COUNTIF('Phase 03 Patient & Records'!$O$2:$O$101,"P3-S04"),"PASS",IF(COUNTIFS('Phase 03 Patient & Records'!$O$2:$O$101,"P3-S04",'Phase 03 Patient & Records'!$G$2:$G$101,"PASS")+COUNTIFS('Phase 03 Patient & Records'!$O$2:$O$101,"P3-S04",'Phase 03 Patient & Records'!$G$2:$G$101,"BLOCKED")>0,"IN PROGRESS","NOT STARTED")))
A8: P3-S05 | B8: Phase 03 Patient & Records | C8: =COUNTIF('Phase 03 Patient & Records'!$O$2:$O$101,"P3-S05") | D8: =COUNTIFS('Phase 03 Patient & Records'!$O$2:$O$101,"P3-S05",'Phase 03 Patient & Records'!$G$2:$G$101,"PASS") | E8: =COUNTIFS('Phase 03 Patient & Records'!$O$2:$O$101,"P3-S05",'Phase 03 Patient & Records'!$G$2:$G$101,"FAIL") | F8: =COUNTIF('Phase 03 Patient & Records'!$O$2:$O$101,"P3-S05")-COUNTIFS('Phase 03 Patient & Records'!$O$2:$O$101,"P3-S05",'Phase 03 Patient & Records'!$G$2:$G$101,"PASS")-COUNTIFS('Phase 03 Patient & Records'!$O$2:$O$101,"P3-S05",'Phase 03 Patient & Records'!$G$2:$G$101,"FAIL")-COUNTIFS('Phase 03 Patient & Records'!$O$2:$O$101,"P3-S05",'Phase 03 Patient & Records'!$G$2:$G$101,"BLOCKED") | G8: =IF(COUNTIFS('Phase 03 Patient & Records'!$O$2:$O$101,"P3-S05",'Phase 03 Patient & Records'!$G$2:$G$101,"FAIL")>0,"FAIL",IF(COUNTIFS('Phase 03 Patient & Records'!$O$2:$O$101,"P3-S05",'Phase 03 Patient & Records'!$G$2:$G$101,"PASS")=COUNTIF('Phase 03 Patient & Records'!$O$2:$O$101,"P3-S05"),"PASS",IF(COUNTIFS('Phase 03 Patient & Records'!$O$2:$O$101,"P3-S05",'Phase 03 Patient & Records'!$G$2:$G$101,"PASS")+COUNTIFS('Phase 03 Patient & Records'!$O$2:$O$101,"P3-S05",'Phase 03 Patient & Records'!$G$2:$G$101,"BLOCKED")>0,"IN PROGRESS","NOT STARTED")))
A9: P3-S06 | B9: Phase 03 Patient & Records | C9: =COUNTIF('Phase 03 Patient & Records'!$O$2:$O$101,"P3-S06") | D9: =COUNTIFS('Phase 03 Patient & Records'!$O$2:$O$101,"P3-S06",'Phase 03 Patient & Records'!$G$2:$G$101,"PASS") | E9: =COUNTIFS('Phase 03 Patient & Records'!$O$2:$O$101,"P3-S06",'Phase 03 Patient & Records'!$G$2:$G$101,"FAIL") | F9: =COUNTIF('Phase 03 Patient & Records'!$O$2:$O$101,"P3-S06")-COUNTIFS('Phase 03 Patient & Records'!$O$2:$O$101,"P3-S06",'Phase 03 Patient & Records'!$G$2:$G$101,"PASS")-COUNTIFS('Phase 03 Patient & Records'!$O$2:$O$101,"P3-S06",'Phase 03 Patient & Records'!$G$2:$G$101,"FAIL")-COUNTIFS('Phase 03 Patient & Records'!$O$2:$O$101,"P3-S06",'Phase 03 Patient & Records'!$G$2:$G$101,"BLOCKED") | G9: =IF(COUNTIFS('Phase 03 Patient & Records'!$O$2:$O$101,"P3-S06",'Phase 03 Patient & Records'!$G$2:$G$101,"FAIL")>0,"FAIL",IF(COUNTIFS('Phase 03 Patient & Records'!$O$2:$O$101,"P3-S06",'Phase 03 Patient & Records'!$G$2:$G$101,"PASS")=COUNTIF('Phase 03 Patient & Records'!$O$2:$O$101,"P3-S06"),"PASS",IF(COUNTIFS('Phase 03 Patient & Records'!$O$2:$O$101,"P3-S06",'Phase 03 Patient & Records'!$G$2:$G$101,"PASS")+COUNTIFS('Phase 03 Patient & Records'!$O$2:$O$101,"P3-S06",'Phase 03 Patient & Records'!$G$2:$G$101,"BLOCKED")>0,"IN PROGRESS","NOT STARTED")))
A10: P3-S07 | B10: Phase 03 Patient & Records | C10: =COUNTIF('Phase 03 Patient & Records'!$O$2:$O$101,"P3-S07") | D10: =COUNTIFS('Phase 03 Patient & Records'!$O$2:$O$101,"P3-S07",'Phase 03 Patient & Records'!$G$2:$G$101,"PASS") | E10: =COUNTIFS('Phase 03 Patient & Records'!$O$2:$O$101,"P3-S07",'Phase 03 Patient & Records'!$G$2:$G$101,"FAIL") | F10: =COUNTIF('Phase 03 Patient & Records'!$O$2:$O$101,"P3-S07")-COUNTIFS('Phase 03 Patient & Records'!$O$2:$O$101,"P3-S07",'Phase 03 Patient & Records'!$G$2:$G$101,"PASS")-COUNTIFS('Phase 03 Patient & Records'!$O$2:$O$101,"P3-S07",'Phase 03 Patient & Records'!$G$2:$G$101,"FAIL")-COUNTIFS('Phase 03 Patient & Records'!$O$2:$O$101,"P3-S07",'Phase 03 Patient & Records'!$G$2:$G$101,"BLOCKED") | G10: =IF(COUNTIFS('Phase 03 Patient & Records'!$O$2:$O$101,"P3-S07",'Phase 03 Patient & Records'!$G$2:$G$101,"FAIL")>0,"FAIL",IF(COUNTIFS('Phase 03 Patient & Records'!$O$2:$O$101,"P3-S07",'Phase 03 Patient & Records'!$G$2:$G$101,"PASS")=COUNTIF('Phase 03 Patient & Records'!$O$2:$O$101,"P3-S07"),"PASS",IF(COUNTIFS('Phase 03 Patient & Records'!$O$2:$O$101,"P3-S07",'Phase 03 Patient & Records'!$G$2:$G$101,"PASS")+COUNTIFS('Phase 03 Patient & Records'!$O$2:$O$101,"P3-S07",'Phase 03 Patient & Records'!$G$2:$G$101,"BLOCKED")>0,"IN PROGRESS","NOT STARTED")))
A11: P3-S08 | B11: Phase 03 Patient & Records | C11: =COUNTIF('Phase 03 Patient & Records'!$O$2:$O$101,"P3-S08") | D11: =COUNTIFS('Phase 03 Patient & Records'!$O$2:$O$101,"P3-S08",'Phase 03 Patient & Records'!$G$2:$G$101,"PASS") | E11: =COUNTIFS('Phase 03 Patient & Records'!$O$2:$O$101,"P3-S08",'Phase 03 Patient & Records'!$G$2:$G$101,"FAIL") | F11: =COUNTIF('Phase 03 Patient & Records'!$O$2:$O$101,"P3-S08")-COUNTIFS('Phase 03 Patient & Records'!$O$2:$O$101,"P3-S08",'Phase 03 Patient & Records'!$G$2:$G$101,"PASS")-COUNTIFS('Phase 03 Patient & Records'!$O$2:$O$101,"P3-S08",'Phase 03 Patient & Records'!$G$2:$G$101,"FAIL")-COUNTIFS('Phase 03 Patient & Records'!$O$2:$O$101,"P3-S08",'Phase 03 Patient & Records'!$G$2:$G$101,"BLOCKED") | G11: =IF(COUNTIFS('Phase 03 Patient & Records'!$O$2:$O$101,"P3-S08",'Phase 03 Patient & Records'!$G$2:$G$101,"FAIL")>0,"FAIL",IF(COUNTIFS('Phase 03 Patient & Records'!$O$2:$O$101,"P3-S08",'Phase 03 Patient & Records'!$G$2:$G$101,"PASS")=COUNTIF('Phase 03 Patient & Records'!$O$2:$O$101,"P3-S08"),"PASS",IF(COUNTIFS('Phase 03 Patient & Records'!$O$2:$O$101,"P3-S08",'Phase 03 Patient & Records'!$G$2:$G$101,"PASS")+COUNTIFS('Phase 03 Patient & Records'!$O$2:$O$101,"P3-S08",'Phase 03 Patient & Records'!$G$2:$G$101,"BLOCKED")>0,"IN PROGRESS","NOT STARTED")))
A12: P3-S09 | B12: Phase 03 Patient & Records | C12: =COUNTIF('Phase 03 Patient & Records'!$O$2:$O$101,"P3-S09") | D12: =COUNTIFS('Phase 03 Patient & Records'!$O$2:$O$101,"P3-S09",'Phase 03 Patient & Records'!$G$2:$G$101,"PASS") | E12: =COUNTIFS('Phase 03 Patient & Records'!$O$2:$O$101,"P3-S09",'Phase 03 Patient & Records'!$G$2:$G$101,"FAIL") | F12: =COUNTIF('Phase 03 Patient & Records'!$O$2:$O$101,"P3-S09")-COUNTIFS('Phase 03 Patient & Records'!$O$2:$O$101,"P3-S09",'Phase 03 Patient & Records'!$G$2:$G$101,"PASS")-COUNTIFS('Phase 03 Patient & Records'!$O$2:$O$101,"P3-S09",'Phase 03 Patient & Records'!$G$2:$G$101,"FAIL")-COUNTIFS('Phase 03 Patient & Records'!$O$2:$O$101,"P3-S09",'Phase 03 Patient & Records'!$G$2:$G$101,"BLOCKED") | G12: =IF(COUNTIFS('Phase 03 Patient & Records'!$O$2:$O$101,"P3-S09",'Phase 03 Patient & Records'!$G$2:$G$101,"FAIL")>0,"FAIL",IF(COUNTIFS('Phase 03 Patient & Records'!$O$2:$O$101,"P3-S09",'Phase 03 Patient & Records'!$G$2:$G$101,"PASS")=COUNTIF('Phase 03 Patient & Records'!$O$2:$O$101,"P3-S09"),"PASS",IF(COUNTIFS('Phase 03 Patient & Records'!$O$2:$O$101,"P3-S09",'Phase 03 Patient & Records'!$G$2:$G$101,"PASS")+COUNTIFS('Phase 03 Patient & Records'!$O$2:$O$101,"P3-S09",'Phase 03 Patient & Records'!$G$2:$G$101,"BLOCKED")>0,"IN PROGRESS","NOT STARTED")))
A13: P3-S10 | B13: Phase 03 Patient & Records | C13: =COUNTIF('Phase 03 Patient & Records'!$O$2:$O$101,"P3-S10") | D13: =COUNTIFS('Phase 03 Patient & Records'!$O$2:$O$101,"P3-S10",'Phase 03 Patient & Records'!$G$2:$G$101,"PASS") | E13: =COUNTIFS('Phase 03 Patient & Records'!$O$2:$O$101,"P3-S10",'Phase 03 Patient & Records'!$G$2:$G$101,"FAIL") | F13: =COUNTIF('Phase 03 Patient & Records'!$O$2:$O$101,"P3-S10")-COUNTIFS('Phase 03 Patient & Records'!$O$2:$O$101,"P3-S10",'Phase 03 Patient & Records'!$G$2:$G$101,"PASS")-COUNTIFS('Phase 03 Patient & Records'!$O$2:$O$101,"P3-S10",'Phase 03 Patient & Records'!$G$2:$G$101,"FAIL")-COUNTIFS('Phase 03 Patient & Records'!$O$2:$O$101,"P3-S10",'Phase 03 Patient & Records'!$G$2:$G$101,"BLOCKED") | G13: =IF(COUNTIFS('Phase 03 Patient & Records'!$O$2:$O$101,"P3-S10",'Phase 03 Patient & Records'!$G$2:$G$101,"FAIL")>0,"FAIL",IF(COUNTIFS('Phase 03 Patient & Records'!$O$2:$O$101,"P3-S10",'Phase 03 Patient & Records'!$G$2:$G$101,"PASS")=COUNTIF('Phase 03 Patient & Records'!$O$2:$O$101,"P3-S10"),"PASS",IF(COUNTIFS('Phase 03 Patient & Records'!$O$2:$O$101,"P3-S10",'Phase 03 Patient & Records'!$G$2:$G$101,"PASS")+COUNTIFS('Phase 03 Patient & Records'!$O$2:$O$101,"P3-S10",'Phase 03 Patient & Records'!$G$2:$G$101,"BLOCKED")>0,"IN PROGRESS","NOT STARTED")))
A14: P3-S11 | B14: Phase 03 Patient & Records | C14: =COUNTIF('Phase 03 Patient & Records'!$O$2:$O$101,"P3-S11") | D14: =COUNTIFS('Phase 03 Patient & Records'!$O$2:$O$101,"P3-S11",'Phase 03 Patient & Records'!$G$2:$G$101,"PASS") | E14: =COUNTIFS('Phase 03 Patient & Records'!$O$2:$O$101,"P3-S11",'Phase 03 Patient & Records'!$G$2:$G$101,"FAIL") | F14: =COUNTIF('Phase 03 Patient & Records'!$O$2:$O$101,"P3-S11")-COUNTIFS('Phase 03 Patient & Records'!$O$2:$O$101,"P3-S11",'Phase 03 Patient & Records'!$G$2:$G$101,"PASS")-COUNTIFS('Phase 03 Patient & Records'!$O$2:$O$101,"P3-S11",'Phase 03 Patient & Records'!$G$2:$G$101,"FAIL")-COUNTIFS('Phase 03 Patient & Records'!$O$2:$O$101,"P3-S11",'Phase 03 Patient & Records'!$G$2:$G$101,"BLOCKED") | G14: =IF(COUNTIFS('Phase 03 Patient & Records'!$O$2:$O$101,"P3-S11",'Phase 03 Patient & Records'!$G$2:$G$101,"FAIL")>0,"FAIL",IF(COUNTIFS('Phase 03 Patient & Records'!$O$2:$O$101,"P3-S11",'Phase 03 Patient & Records'!$G$2:$G$101,"PASS")=COUNTIF('Phase 03 Patient & Records'!$O$2:$O$101,"P3-S11"),"PASS",IF(COUNTIFS('Phase 03 Patient & Records'!$O$2:$O$101,"P3-S11",'Phase 03 Patient & Records'!$G$2:$G$101,"PASS")+COUNTIFS('Phase 03 Patient & Records'!$O$2:$O$101,"P3-S11",'Phase 03 Patient & Records'!$G$2:$G$101,"BLOCKED")>0,"IN PROGRESS","NOT STARTED")))
A15: P3-S12 | B15: Phase 03 Patient & Records | C15: =COUNTIF('Phase 03 Patient & Records'!$O$2:$O$101,"P3-S12") | D15: =COUNTIFS('Phase 03 Patient & Records'!$O$2:$O$101,"P3-S12",'Phase 03 Patient & Records'!$G$2:$G$101,"PASS") | E15: =COUNTIFS('Phase 03 Patient & Records'!$O$2:$O$101,"P3-S12",'Phase 03 Patient & Records'!$G$2:$G$101,"FAIL") | F15: =COUNTIF('Phase 03 Patient & Records'!$O$2:$O$101,"P3-S12")-COUNTIFS('Phase 03 Patient & Records'!$O$2:$O$101,"P3-S12",'Phase 03 Patient & Records'!$G$2:$G$101,"PASS")-COUNTIFS('Phase 03 Patient & Records'!$O$2:$O$101,"P3-S12",'Phase 03 Patient & Records'!$G$2:$G$101,"FAIL")-COUNTIFS('Phase 03 Patient & Records'!$O$2:$O$101,"P3-S12",'Phase 03 Patient & Records'!$G$2:$G$101,"BLOCKED") | G15: =IF(COUNTIFS('Phase 03 Patient & Records'!$O$2:$O$101,"P3-S12",'Phase 03 Patient & Records'!$G$2:$G$101,"FAIL")>0,"FAIL",IF(COUNTIFS('Phase 03 Patient & Records'!$O$2:$O$101,"P3-S12",'Phase 03 Patient & Records'!$G$2:$G$101,"PASS")=COUNTIF('Phase 03 Patient & Records'!$O$2:$O$101,"P3-S12"),"PASS",IF(COUNTIFS('Phase 03 Patient & Records'!$O$2:$O$101,"P3-S12",'Phase 03 Patient & Records'!$G$2:$G$101,"PASS")+COUNTIFS('Phase 03 Patient & Records'!$O$2:$O$101,"P3-S12",'Phase 03 Patient & Records'!$G$2:$G$101,"BLOCKED")>0,"IN PROGRESS","NOT STARTED")))
A16: P4-S01 | B16: Phase 04 OPD Journey | C16: =COUNTIF('Phase 04 OPD Journey'!$O$2:$O$261,"P4-S01") | D16: =COUNTIFS('Phase 04 OPD Journey'!$O$2:$O$261,"P4-S01",'Phase 04 OPD Journey'!$G$2:$G$261,"PASS") | E16: =COUNTIFS('Phase 04 OPD Journey'!$O$2:$O$261,"P4-S01",'Phase 04 OPD Journey'!$G$2:$G$261,"FAIL") | F16: =COUNTIF('Phase 04 OPD Journey'!$O$2:$O$261,"P4-S01")-COUNTIFS('Phase 04 OPD Journey'!$O$2:$O$261,"P4-S01",'Phase 04 OPD Journey'!$G$2:$G$261,"PASS")-COUNTIFS('Phase 04 OPD Journey'!$O$2:$O$261,"P4-S01",'Phase 04 OPD Journey'!$G$2:$G$261,"FAIL")-COUNTIFS('Phase 04 OPD Journey'!$O$2:$O$261,"P4-S01",'Phase 04 OPD Journey'!$G$2:$G$261,"BLOCKED") | G16: =IF(COUNTIFS('Phase 04 OPD Journey'!$O$2:$O$261,"P4-S01",'Phase 04 OPD Journey'!$G$2:$G$261,"FAIL")>0,"FAIL",IF(COUNTIFS('Phase 04 OPD Journey'!$O$2:$O$261,"P4-S01",'Phase 04 OPD Journey'!$G$2:$G$261,"PASS")=COUNTIF('Phase 04 OPD Journey'!$O$2:$O$261,"P4-S01"),"PASS",IF(COUNTIFS('Phase 04 OPD Journey'!$O$2:$O$261,"P4-S01",'Phase 04 OPD Journey'!$G$2:$G$261,"PASS")+COUNTIFS('Phase 04 OPD Journey'!$O$2:$O$261,"P4-S01",'Phase 04 OPD Journey'!$G$2:$G$261,"BLOCKED")>0,"IN PROGRESS","NOT STARTED")))
A17: P4-S02 | B17: Phase 04 OPD Journey | C17: =COUNTIF('Phase 04 OPD Journey'!$O$2:$O$261,"P4-S02") | D17: =COUNTIFS('Phase 04 OPD Journey'!$O$2:$O$261,"P4-S02",'Phase 04 OPD Journey'!$G$2:$G$261,"PASS") | E17: =COUNTIFS('Phase 04 OPD Journey'!$O$2:$O$261,"P4-S02",'Phase 04 OPD Journey'!$G$2:$G$261,"FAIL") | F17: =COUNTIF('Phase 04 OPD Journey'!$O$2:$O$261,"P4-S02")-COUNTIFS('Phase 04 OPD Journey'!$O$2:$O$261,"P4-S02",'Phase 04 OPD Journey'!$G$2:$G$261,"PASS")-COUNTIFS('Phase 04 OPD Journey'!$O$2:$O$261,"P4-S02",'Phase 04 OPD Journey'!$G$2:$G$261,"FAIL")-COUNTIFS('Phase 04 OPD Journey'!$O$2:$O$261,"P4-S02",'Phase 04 OPD Journey'!$G$2:$G$261,"BLOCKED") | G17: =IF(COUNTIFS('Phase 04 OPD Journey'!$O$2:$O$261,"P4-S02",'Phase 04 OPD Journey'!$G$2:$G$261,"FAIL")>0,"FAIL",IF(COUNTIFS('Phase 04 OPD Journey'!$O$2:$O$261,"P4-S02",'Phase 04 OPD Journey'!$G$2:$G$261,"PASS")=COUNTIF('Phase 04 OPD Journey'!$O$2:$O$261,"P4-S02"),"PASS",IF(COUNTIFS('Phase 04 OPD Journey'!$O$2:$O$261,"P4-S02",'Phase 04 OPD Journey'!$G$2:$G$261,"PASS")+COUNTIFS('Phase 04 OPD Journey'!$O$2:$O$261,"P4-S02",'Phase 04 OPD Journey'!$G$2:$G$261,"BLOCKED")>0,"IN PROGRESS","NOT STARTED")))
A18: P4-S03 | B18: Phase 04 OPD Journey | C18: =COUNTIF('Phase 04 OPD Journey'!$O$2:$O$261,"P4-S03") | D18: =COUNTIFS('Phase 04 OPD Journey'!$O$2:$O$261,"P4-S03",'Phase 04 OPD Journey'!$G$2:$G$261,"PASS") | E18: =COUNTIFS('Phase 04 OPD Journey'!$O$2:$O$261,"P4-S03",'Phase 04 OPD Journey'!$G$2:$G$261,"FAIL") | F18: =COUNTIF('Phase 04 OPD Journey'!$O$2:$O$261,"P4-S03")-COUNTIFS('Phase 04 OPD Journey'!$O$2:$O$261,"P4-S03",'Phase 04 OPD Journey'!$G$2:$G$261,"PASS")-COUNTIFS('Phase 04 OPD Journey'!$O$2:$O$261,"P4-S03",'Phase 04 OPD Journey'!$G$2:$G$261,"FAIL")-COUNTIFS('Phase 04 OPD Journey'!$O$2:$O$261,"P4-S03",'Phase 04 OPD Journey'!$G$2:$G$261,"BLOCKED") | G18: =IF(COUNTIFS('Phase 04 OPD Journey'!$O$2:$O$261,"P4-S03",'Phase 04 OPD Journey'!$G$2:$G$261,"FAIL")>0,"FAIL",IF(COUNTIFS('Phase 04 OPD Journey'!$O$2:$O$261,"P4-S03",'Phase 04 OPD Journey'!$G$2:$G$261,"PASS")=COUNTIF('Phase 04 OPD Journey'!$O$2:$O$261,"P4-S03"),"PASS",IF(COUNTIFS('Phase 04 OPD Journey'!$O$2:$O$261,"P4-S03",'Phase 04 OPD Journey'!$G$2:$G$261,"PASS")+COUNTIFS('Phase 04 OPD Journey'!$O$2:$O$261,"P4-S03",'Phase 04 OPD Journey'!$G$2:$G$261,"BLOCKED")>0,"IN PROGRESS","NOT STARTED")))
A19: P4-S04 | B19: Phase 04 OPD Journey | C19: =COUNTIF('Phase 04 OPD Journey'!$O$2:$O$261,"P4-S04") | D19: =COUNTIFS('Phase 04 OPD Journey'!$O$2:$O$261,"P4-S04",'Phase 04 OPD Journey'!$G$2:$G$261,"PASS") | E19: =COUNTIFS('Phase 04 OPD Journey'!$O$2:$O$261,"P4-S04",'Phase 04 OPD Journey'!$G$2:$G$261,"FAIL") | F19: =COUNTIF('Phase 04 OPD Journey'!$O$2:$O$261,"P4-S04")-COUNTIFS('Phase 04 OPD Journey'!$O$2:$O$261,"P4-S04",'Phase 04 OPD Journey'!$G$2:$G$261,"PASS")-COUNTIFS('Phase 04 OPD Journey'!$O$2:$O$261,"P4-S04",'Phase 04 OPD Journey'!$G$2:$G$261,"FAIL")-COUNTIFS('Phase 04 OPD Journey'!$O$2:$O$261,"P4-S04",'Phase 04 OPD Journey'!$G$2:$G$261,"BLOCKED") | G19: =IF(COUNTIFS('Phase 04 OPD Journey'!$O$2:$O$261,"P4-S04",'Phase 04 OPD Journey'!$G$2:$G$261,"FAIL")>0,"FAIL",IF(COUNTIFS('Phase 04 OPD Journey'!$O$2:$O$261,"P4-S04",'Phase 04 OPD Journey'!$G$2:$G$261,"PASS")=COUNTIF('Phase 04 OPD Journey'!$O$2:$O$261,"P4-S04"),"PASS",IF(COUNTIFS('Phase 04 OPD Journey'!$O$2:$O$261,"P4-S04",'Phase 04 OPD Journey'!$G$2:$G$261,"PASS")+COUNTIFS('Phase 04 OPD Journey'!$O$2:$O$261,"P4-S04",'Phase 04 OPD Journey'!$G$2:$G$261,"BLOCKED")>0,"IN PROGRESS","NOT STARTED")))
A20: P4-S05 | B20: Phase 04 OPD Journey | C20: =COUNTIF('Phase 04 OPD Journey'!$O$2:$O$261,"P4-S05") | D20: =COUNTIFS('Phase 04 OPD Journey'!$O$2:$O$261,"P4-S05",'Phase 04 OPD Journey'!$G$2:$G$261,"PASS") | E20: =COUNTIFS('Phase 04 OPD Journey'!$O$2:$O$261,"P4-S05",'Phase 04 OPD Journey'!$G$2:$G$261,"FAIL") | F20: =COUNTIF('Phase 04 OPD Journey'!$O$2:$O$261,"P4-S05")-COUNTIFS('Phase 04 OPD Journey'!$O$2:$O$261,"P4-S05",'Phase 04 OPD Journey'!$G$2:$G$261,"PASS")-COUNTIFS('Phase 04 OPD Journey'!$O$2:$O$261,"P4-S05",'Phase 04 OPD Journey'!$G$2:$G$261,"FAIL")-COUNTIFS('Phase 04 OPD Journey'!$O$2:$O$261,"P4-S05",'Phase 04 OPD Journey'!$G$2:$G$261,"BLOCKED") | G20: =IF(COUNTIFS('Phase 04 OPD Journey'!$O$2:$O$261,"P4-S05",'Phase 04 OPD Journey'!$G$2:$G$261,"FAIL")>0,"FAIL",IF(COUNTIFS('Phase 04 OPD Journey'!$O$2:$O$261,"P4-S05",'Phase 04 OPD Journey'!$G$2:$G$261,"PASS")=COUNTIF('Phase 04 OPD Journey'!$O$2:$O$261,"P4-S05"),"PASS",IF(COUNTIFS('Phase 04 OPD Journey'!$O$2:$O$261,"P4-S05",'Phase 04 OPD Journey'!$G$2:$G$261,"PASS")+COUNTIFS('Phase 04 OPD Journey'!$O$2:$O$261,"P4-S05",'Phase 04 OPD Journey'!$G$2:$G$261,"BLOCKED")>0,"IN PROGRESS","NOT STARTED")))
A21: P4-S06 | B21: Phase 04 OPD Journey | C21: =COUNTIF('Phase 04 OPD Journey'!$O$2:$O$261,"P4-S06") | D21: =COUNTIFS('Phase 04 OPD Journey'!$O$2:$O$261,"P4-S06",'Phase 04 OPD Journey'!$G$2:$G$261,"PASS") | E21: =COUNTIFS('Phase 04 OPD Journey'!$O$2:$O$261,"P4-S06",'Phase 04 OPD Journey'!$G$2:$G$261,"FAIL") | F21: =COUNTIF('Phase 04 OPD Journey'!$O$2:$O$261,"P4-S06")-COUNTIFS('Phase 04 OPD Journey'!$O$2:$O$261,"P4-S06",'Phase 04 OPD Journey'!$G$2:$G$261,"PASS")-COUNTIFS('Phase 04 OPD Journey'!$O$2:$O$261,"P4-S06",'Phase 04 OPD Journey'!$G$2:$G$261,"FAIL")-COUNTIFS('Phase 04 OPD Journey'!$O$2:$O$261,"P4-S06",'Phase 04 OPD Journey'!$G$2:$G$261,"BLOCKED") | G21: =IF(COUNTIFS('Phase 04 OPD Journey'!$O$2:$O$261,"P4-S06",'Phase 04 OPD Journey'!$G$2:$G$261,"FAIL")>0,"FAIL",IF(COUNTIFS('Phase 04 OPD Journey'!$O$2:$O$261,"P4-S06",'Phase 04 OPD Journey'!$G$2:$G$261,"PASS")=COUNTIF('Phase 04 OPD Journey'!$O$2:$O$261,"P4-S06"),"PASS",IF(COUNTIFS('Phase 04 OPD Journey'!$O$2:$O$261,"P4-S06",'Phase 04 OPD Journey'!$G$2:$G$261,"PASS")+COUNTIFS('Phase 04 OPD Journey'!$O$2:$O$261,"P4-S06",'Phase 04 OPD Journey'!$G$2:$G$261,"BLOCKED")>0,"IN PROGRESS","NOT STARTED")))
A22: P4-S07 | B22: Phase 04 OPD Journey | C22: =COUNTIF('Phase 04 OPD Journey'!$O$2:$O$261,"P4-S07") | D22: =COUNTIFS('Phase 04 OPD Journey'!$O$2:$O$261,"P4-S07",'Phase 04 OPD Journey'!$G$2:$G$261,"PASS") | E22: =COUNTIFS('Phase 04 OPD Journey'!$O$2:$O$261,"P4-S07",'Phase 04 OPD Journey'!$G$2:$G$261,"FAIL") | F22: =COUNTIF('Phase 04 OPD Journey'!$O$2:$O$261,"P4-S07")-COUNTIFS('Phase 04 OPD Journey'!$O$2:$O$261,"P4-S07",'Phase 04 OPD Journey'!$G$2:$G$261,"PASS")-COUNTIFS('Phase 04 OPD Journey'!$O$2:$O$261,"P4-S07",'Phase 04 OPD Journey'!$G$2:$G$261,"FAIL")-COUNTIFS('Phase 04 OPD Journey'!$O$2:$O$261,"P4-S07",'Phase 04 OPD Journey'!$G$2:$G$261,"BLOCKED") | G22: =IF(COUNTIFS('Phase 04 OPD Journey'!$O$2:$O$261,"P4-S07",'Phase 04 OPD Journey'!$G$2:$G$261,"FAIL")>0,"FAIL",IF(COUNTIFS('Phase 04 OPD Journey'!$O$2:$O$261,"P4-S07",'Phase 04 OPD Journey'!$G$2:$G$261,"PASS")=COUNTIF('Phase 04 OPD Journey'!$O$2:$O$261,"P4-S07"),"PASS",IF(COUNTIFS('Phase 04 OPD Journey'!$O$2:$O$261,"P4-S07",'Phase 04 OPD Journey'!$G$2:$G$261,"PASS")+COUNTIFS('Phase 04 OPD Journey'!$O$2:$O$261,"P4-S07",'Phase 04 OPD Journey'!$G$2:$G$261,"BLOCKED")>0,"IN PROGRESS","NOT STARTED")))
A23: P4-S08 | B23: Phase 04 OPD Journey | C23: =COUNTIF('Phase 04 OPD Journey'!$O$2:$O$261,"P4-S08") | D23: =COUNTIFS('Phase 04 OPD Journey'!$O$2:$O$261,"P4-S08",'Phase 04 OPD Journey'!$G$2:$G$261,"PASS") | E23: =COUNTIFS('Phase 04 OPD Journey'!$O$2:$O$261,"P4-S08",'Phase 04 OPD Journey'!$G$2:$G$261,"FAIL") | F23: =COUNTIF('Phase 04 OPD Journey'!$O$2:$O$261,"P4-S08")-COUNTIFS('Phase 04 OPD Journey'!$O$2:$O$261,"P4-S08",'Phase 04 OPD Journey'!$G$2:$G$261,"PASS")-COUNTIFS('Phase 04 OPD Journey'!$O$2:$O$261,"P4-S08",'Phase 04 OPD Journey'!$G$2:$G$261,"FAIL")-COUNTIFS('Phase 04 OPD Journey'!$O$2:$O$261,"P4-S08",'Phase 04 OPD Journey'!$G$2:$G$261,"BLOCKED") | G23: =IF(COUNTIFS('Phase 04 OPD Journey'!$O$2:$O$261,"P4-S08",'Phase 04 OPD Journey'!$G$2:$G$261,"FAIL")>0,"FAIL",IF(COUNTIFS('Phase 04 OPD Journey'!$O$2:$O$261,"P4-S08",'Phase 04 OPD Journey'!$G$2:$G$261,"PASS")=COUNTIF('Phase 04 OPD Journey'!$O$2:$O$261,"P4-S08"),"PASS",IF(COUNTIFS('Phase 04 OPD Journey'!$O$2:$O$261,"P4-S08",'Phase 04 OPD Journey'!$G$2:$G$261,"PASS")+COUNTIFS('Phase 04 OPD Journey'!$O$2:$O$261,"P4-S08",'Phase 04 OPD Journey'!$G$2:$G$261,"BLOCKED")>0,"IN PROGRESS","NOT STARTED")))
A24: P4-S09 | B24: Phase 04 OPD Journey | C24: =COUNTIF('Phase 04 OPD Journey'!$O$2:$O$261,"P4-S09") | D24: =COUNTIFS('Phase 04 OPD Journey'!$O$2:$O$261,"P4-S09",'Phase 04 OPD Journey'!$G$2:$G$261,"PASS") | E24: =COUNTIFS('Phase 04 OPD Journey'!$O$2:$O$261,"P4-S09",'Phase 04 OPD Journey'!$G$2:$G$261,"FAIL") | F24: =COUNTIF('Phase 04 OPD Journey'!$O$2:$O$261,"P4-S09")-COUNTIFS('Phase 04 OPD Journey'!$O$2:$O$261,"P4-S09",'Phase 04 OPD Journey'!$G$2:$G$261,"PASS")-COUNTIFS('Phase 04 OPD Journey'!$O$2:$O$261,"P4-S09",'Phase 04 OPD Journey'!$G$2:$G$261,"FAIL")-COUNTIFS('Phase 04 OPD Journey'!$O$2:$O$261,"P4-S09",'Phase 04 OPD Journey'!$G$2:$G$261,"BLOCKED") | G24: =IF(COUNTIFS('Phase 04 OPD Journey'!$O$2:$O$261,"P4-S09",'Phase 04 OPD Journey'!$G$2:$G$261,"FAIL")>0,"FAIL",IF(COUNTIFS('Phase 04 OPD Journey'!$O$2:$O$261,"P4-S09",'Phase 04 OPD Journey'!$G$2:$G$261,"PASS")=COUNTIF('Phase 04 OPD Journey'!$O$2:$O$261,"P4-S09"),"PASS",IF(COUNTIFS('Phase 04 OPD Journey'!$O$2:$O$261,"P4-S09",'Phase 04 OPD Journey'!$G$2:$G$261,"PASS")+COUNTIFS('Phase 04 OPD Journey'!$O$2:$O$261,"P4-S09",'Phase 04 OPD Journey'!$G$2:$G$261,"BLOCKED")>0,"IN PROGRESS","NOT STARTED")))
A25: P4-S10 | B25: Phase 04 OPD Journey | C25: =COUNTIF('Phase 04 OPD Journey'!$O$2:$O$261,"P4-S10") | D25: =COUNTIFS('Phase 04 OPD Journey'!$O$2:$O$261,"P4-S10",'Phase 04 OPD Journey'!$G$2:$G$261,"PASS") | E25: =COUNTIFS('Phase 04 OPD Journey'!$O$2:$O$261,"P4-S10",'Phase 04 OPD Journey'!$G$2:$G$261,"FAIL") | F25: =COUNTIF('Phase 04 OPD Journey'!$O$2:$O$261,"P4-S10")-COUNTIFS('Phase 04 OPD Journey'!$O$2:$O$261,"P4-S10",'Phase 04 OPD Journey'!$G$2:$G$261,"PASS")-COUNTIFS('Phase 04 OPD Journey'!$O$2:$O$261,"P4-S10",'Phase 04 OPD Journey'!$G$2:$G$261,"FAIL")-COUNTIFS('Phase 04 OPD Journey'!$O$2:$O$261,"P4-S10",'Phase 04 OPD Journey'!$G$2:$G$261,"BLOCKED") | G25: =IF(COUNTIFS('Phase 04 OPD Journey'!$O$2:$O$261,"P4-S10",'Phase 04 OPD Journey'!$G$2:$G$261,"FAIL")>0,"FAIL",IF(COUNTIFS('Phase 04 OPD Journey'!$O$2:$O$261,"P4-S10",'Phase 04 OPD Journey'!$G$2:$G$261,"PASS")=COUNTIF('Phase 04 OPD Journey'!$O$2:$O$261,"P4-S10"),"PASS",IF(COUNTIFS('Phase 04 OPD Journey'!$O$2:$O$261,"P4-S10",'Phase 04 OPD Journey'!$G$2:$G$261,"PASS")+COUNTIFS('Phase 04 OPD Journey'!$O$2:$O$261,"P4-S10",'Phase 04 OPD Journey'!$G$2:$G$261,"BLOCKED")>0,"IN PROGRESS","NOT STARTED")))
A26: P4-S11 | B26: Phase 04 OPD Journey | C26: =COUNTIF('Phase 04 OPD Journey'!$O$2:$O$261,"P4-S11") | D26: =COUNTIFS('Phase 04 OPD Journey'!$O$2:$O$261,"P4-S11",'Phase 04 OPD Journey'!$G$2:$G$261,"PASS") | E26: =COUNTIFS('Phase 04 OPD Journey'!$O$2:$O$261,"P4-S11",'Phase 04 OPD Journey'!$G$2:$G$261,"FAIL") | F26: =COUNTIF('Phase 04 OPD Journey'!$O$2:$O$261,"P4-S11")-COUNTIFS('Phase 04 OPD Journey'!$O$2:$O$261,"P4-S11",'Phase 04 OPD Journey'!$G$2:$G$261,"PASS")-COUNTIFS('Phase 04 OPD Journey'!$O$2:$O$261,"P4-S11",'Phase 04 OPD Journey'!$G$2:$G$261,"FAIL")-COUNTIFS('Phase 04 OPD Journey'!$O$2:$O$261,"P4-S11",'Phase 04 OPD Journey'!$G$2:$G$261,"BLOCKED") | G26: =IF(COUNTIFS('Phase 04 OPD Journey'!$O$2:$O$261,"P4-S11",'Phase 04 OPD Journey'!$G$2:$G$261,"FAIL")>0,"FAIL",IF(COUNTIFS('Phase 04 OPD Journey'!$O$2:$O$261,"P4-S11",'Phase 04 OPD Journey'!$G$2:$G$261,"PASS")=COUNTIF('Phase 04 OPD Journey'!$O$2:$O$261,"P4-S11"),"PASS",IF(COUNTIFS('Phase 04 OPD Journey'!$O$2:$O$261,"P4-S11",'Phase 04 OPD Journey'!$G$2:$G$261,"PASS")+COUNTIFS('Phase 04 OPD Journey'!$O$2:$O$261,"P4-S11",'Phase 04 OPD Journey'!$G$2:$G$261,"BLOCKED")>0,"IN PROGRESS","NOT STARTED")))
A27: P4-S12 | B27: Phase 04 OPD Journey | C27: =COUNTIF('Phase 04 OPD Journey'!$O$2:$O$261,"P4-S12") | D27: =COUNTIFS('Phase 04 OPD Journey'!$O$2:$O$261,"P4-S12",'Phase 04 OPD Journey'!$G$2:$G$261,"PASS") | E27: =COUNTIFS('Phase 04 OPD Journey'!$O$2:$O$261,"P4-S12",'Phase 04 OPD Journey'!$G$2:$G$261,"FAIL") | F27: =COUNTIF('Phase 04 OPD Journey'!$O$2:$O$261,"P4-S12")-COUNTIFS('Phase 04 OPD Journey'!$O$2:$O$261,"P4-S12",'Phase 04 OPD Journey'!$G$2:$G$261,"PASS")-COUNTIFS('Phase 04 OPD Journey'!$O$2:$O$261,"P4-S12",'Phase 04 OPD Journey'!$G$2:$G$261,"FAIL")-COUNTIFS('Phase 04 OPD Journey'!$O$2:$O$261,"P4-S12",'Phase 04 OPD Journey'!$G$2:$G$261,"BLOCKED") | G27: =IF(COUNTIFS('Phase 04 OPD Journey'!$O$2:$O$261,"P4-S12",'Phase 04 OPD Journey'!$G$2:$G$261,"FAIL")>0,"FAIL",IF(COUNTIFS('Phase 04 OPD Journey'!$O$2:$O$261,"P4-S12",'Phase 04 OPD Journey'!$G$2:$G$261,"PASS")=COUNTIF('Phase 04 OPD Journey'!$O$2:$O$261,"P4-S12"),"PASS",IF(COUNTIFS('Phase 04 OPD Journey'!$O$2:$O$261,"P4-S12",'Phase 04 OPD Journey'!$G$2:$G$261,"PASS")+COUNTIFS('Phase 04 OPD Journey'!$O$2:$O$261,"P4-S12",'Phase 04 OPD Journey'!$G$2:$G$261,"BLOCKED")>0,"IN PROGRESS","NOT STARTED")))
A28: P4-S13 | B28: Phase 04 OPD Journey | C28: =COUNTIF('Phase 04 OPD Journey'!$O$2:$O$261,"P4-S13") | D28: =COUNTIFS('Phase 04 OPD Journey'!$O$2:$O$261,"P4-S13",'Phase 04 OPD Journey'!$G$2:$G$261,"PASS") | E28: =COUNTIFS('Phase 04 OPD Journey'!$O$2:$O$261,"P4-S13",'Phase 04 OPD Journey'!$G$2:$G$261,"FAIL") | F28: =COUNTIF('Phase 04 OPD Journey'!$O$2:$O$261,"P4-S13")-COUNTIFS('Phase 04 OPD Journey'!$O$2:$O$261,"P4-S13",'Phase 04 OPD Journey'!$G$2:$G$261,"PASS")-COUNTIFS('Phase 04 OPD Journey'!$O$2:$O$261,"P4-S13",'Phase 04 OPD Journey'!$G$2:$G$261,"FAIL")-COUNTIFS('Phase 04 OPD Journey'!$O$2:$O$261,"P4-S13",'Phase 04 OPD Journey'!$G$2:$G$261,"BLOCKED") | G28: =IF(COUNTIFS('Phase 04 OPD Journey'!$O$2:$O$261,"P4-S13",'Phase 04 OPD Journey'!$G$2:$G$261,"FAIL")>0,"FAIL",IF(COUNTIFS('Phase 04 OPD Journey'!$O$2:$O$261,"P4-S13",'Phase 04 OPD Journey'!$G$2:$G$261,"PASS")=COUNTIF('Phase 04 OPD Journey'!$O$2:$O$261,"P4-S13"),"PASS",IF(COUNTIFS('Phase 04 OPD Journey'!$O$2:$O$261,"P4-S13",'Phase 04 OPD Journey'!$G$2:$G$261,"PASS")+COUNTIFS('Phase 04 OPD Journey'!$O$2:$O$261,"P4-S13",'Phase 04 OPD Journey'!$G$2:$G$261,"BLOCKED")>0,"IN PROGRESS","NOT STARTED")))
A29: P4-S14 | B29: Phase 04 OPD Journey | C29: =COUNTIF('Phase 04 OPD Journey'!$O$2:$O$261,"P4-S14") | D29: =COUNTIFS('Phase 04 OPD Journey'!$O$2:$O$261,"P4-S14",'Phase 04 OPD Journey'!$G$2:$G$261,"PASS") | E29: =COUNTIFS('Phase 04 OPD Journey'!$O$2:$O$261,"P4-S14",'Phase 04 OPD Journey'!$G$2:$G$261,"FAIL") | F29: =COUNTIF('Phase 04 OPD Journey'!$O$2:$O$261,"P4-S14")-COUNTIFS('Phase 04 OPD Journey'!$O$2:$O$261,"P4-S14",'Phase 04 OPD Journey'!$G$2:$G$261,"PASS")-COUNTIFS('Phase 04 OPD Journey'!$O$2:$O$261,"P4-S14",'Phase 04 OPD Journey'!$G$2:$G$261,"FAIL")-COUNTIFS('Phase 04 OPD Journey'!$O$2:$O$261,"P4-S14",'Phase 04 OPD Journey'!$G$2:$G$261,"BLOCKED") | G29: =IF(COUNTIFS('Phase 04 OPD Journey'!$O$2:$O$261,"P4-S14",'Phase 04 OPD Journey'!$G$2:$G$261,"FAIL")>0,"FAIL",IF(COUNTIFS('Phase 04 OPD Journey'!$O$2:$O$261,"P4-S14",'Phase 04 OPD Journey'!$G$2:$G$261,"PASS")=COUNTIF('Phase 04 OPD Journey'!$O$2:$O$261,"P4-S14"),"PASS",IF(COUNTIFS('Phase 04 OPD Journey'!$O$2:$O$261,"P4-S14",'Phase 04 OPD Journey'!$G$2:$G$261,"PASS")+COUNTIFS('Phase 04 OPD Journey'!$O$2:$O$261,"P4-S14",'Phase 04 OPD Journey'!$G$2:$G$261,"BLOCKED")>0,"IN PROGRESS","NOT STARTED")))
A30: P4-S15 | B30: Phase 04 OPD Journey | C30: =COUNTIF('Phase 04 OPD Journey'!$O$2:$O$261,"P4-S15") | D30: =COUNTIFS('Phase 04 OPD Journey'!$O$2:$O$261,"P4-S15",'Phase 04 OPD Journey'!$G$2:$G$261,"PASS") | E30: =COUNTIFS('Phase 04 OPD Journey'!$O$2:$O$261,"P4-S15",'Phase 04 OPD Journey'!$G$2:$G$261,"FAIL") | F30: =COUNTIF('Phase 04 OPD Journey'!$O$2:$O$261,"P4-S15")-COUNTIFS('Phase 04 OPD Journey'!$O$2:$O$261,"P4-S15",'Phase 04 OPD Journey'!$G$2:$G$261,"PASS")-COUNTIFS('Phase 04 OPD Journey'!$O$2:$O$261,"P4-S15",'Phase 04 OPD Journey'!$G$2:$G$261,"FAIL")-COUNTIFS('Phase 04 OPD Journey'!$O$2:$O$261,"P4-S15",'Phase 04 OPD Journey'!$G$2:$G$261,"BLOCKED") | G30: =IF(COUNTIFS('Phase 04 OPD Journey'!$O$2:$O$261,"P4-S15",'Phase 04 OPD Journey'!$G$2:$G$261,"FAIL")>0,"FAIL",IF(COUNTIFS('Phase 04 OPD Journey'!$O$2:$O$261,"P4-S15",'Phase 04 OPD Journey'!$G$2:$G$261,"PASS")=COUNTIF('Phase 04 OPD Journey'!$O$2:$O$261,"P4-S15"),"PASS",IF(COUNTIFS('Phase 04 OPD Journey'!$O$2:$O$261,"P4-S15",'Phase 04 OPD Journey'!$G$2:$G$261,"PASS")+COUNTIFS('Phase 04 OPD Journey'!$O$2:$O$261,"P4-S15",'Phase 04 OPD Journey'!$G$2:$G$261,"BLOCKED")>0,"IN PROGRESS","NOT STARTED")))
A31: P4-S16 | B31: Phase 04 OPD Journey | C31: =COUNTIF('Phase 04 OPD Journey'!$O$2:$O$261,"P4-S16") | D31: =COUNTIFS('Phase 04 OPD Journey'!$O$2:$O$261,"P4-S16",'Phase 04 OPD Journey'!$G$2:$G$261,"PASS") | E31: =COUNTIFS('Phase 04 OPD Journey'!$O$2:$O$261,"P4-S16",'Phase 04 OPD Journey'!$G$2:$G$261,"FAIL") | F31: =COUNTIF('Phase 04 OPD Journey'!$O$2:$O$261,"P4-S16")-COUNTIFS('Phase 04 OPD Journey'!$O$2:$O$261,"P4-S16",'Phase 04 OPD Journey'!$G$2:$G$261,"PASS")-COUNTIFS('Phase 04 OPD Journey'!$O$2:$O$261,"P4-S16",'Phase 04 OPD Journey'!$G$2:$G$261,"FAIL")-COUNTIFS('Phase 04 OPD Journey'!$O$2:$O$261,"P4-S16",'Phase 04 OPD Journey'!$G$2:$G$261,"BLOCKED") | G31: =IF(COUNTIFS('Phase 04 OPD Journey'!$O$2:$O$261,"P4-S16",'Phase 04 OPD Journey'!$G$2:$G$261,"FAIL")>0,"FAIL",IF(COUNTIFS('Phase 04 OPD Journey'!$O$2:$O$261,"P4-S16",'Phase 04 OPD Journey'!$G$2:$G$261,"PASS")=COUNTIF('Phase 04 OPD Journey'!$O$2:$O$261,"P4-S16"),"PASS",IF(COUNTIFS('Phase 04 OPD Journey'!$O$2:$O$261,"P4-S16",'Phase 04 OPD Journey'!$G$2:$G$261,"PASS")+COUNTIFS('Phase 04 OPD Journey'!$O$2:$O$261,"P4-S16",'Phase 04 OPD Journey'!$G$2:$G$261,"BLOCKED")>0,"IN PROGRESS","NOT STARTED")))
A32: P4-S17 | B32: Phase 04 OPD Journey | C32: =COUNTIF('Phase 04 OPD Journey'!$O$2:$O$261,"P4-S17") | D32: =COUNTIFS('Phase 04 OPD Journey'!$O$2:$O$261,"P4-S17",'Phase 04 OPD Journey'!$G$2:$G$261,"PASS") | E32: =COUNTIFS('Phase 04 OPD Journey'!$O$2:$O$261,"P4-S17",'Phase 04 OPD Journey'!$G$2:$G$261,"FAIL") | F32: =COUNTIF('Phase 04 OPD Journey'!$O$2:$O$261,"P4-S17")-COUNTIFS('Phase 04 OPD Journey'!$O$2:$O$261,"P4-S17",'Phase 04 OPD Journey'!$G$2:$G$261,"PASS")-COUNTIFS('Phase 04 OPD Journey'!$O$2:$O$261,"P4-S17",'Phase 04 OPD Journey'!$G$2:$G$261,"FAIL")-COUNTIFS('Phase 04 OPD Journey'!$O$2:$O$261,"P4-S17",'Phase 04 OPD Journey'!$G$2:$G$261,"BLOCKED") | G32: =IF(COUNTIFS('Phase 04 OPD Journey'!$O$2:$O$261,"P4-S17",'Phase 04 OPD Journey'!$G$2:$G$261,"FAIL")>0,"FAIL",IF(COUNTIFS('Phase 04 OPD Journey'!$O$2:$O$261,"P4-S17",'Phase 04 OPD Journey'!$G$2:$G$261,"PASS")=COUNTIF('Phase 04 OPD Journey'!$O$2:$O$261,"P4-S17"),"PASS",IF(COUNTIFS('Phase 04 OPD Journey'!$O$2:$O$261,"P4-S17",'Phase 04 OPD Journey'!$G$2:$G$261,"PASS")+COUNTIFS('Phase 04 OPD Journey'!$O$2:$O$261,"P4-S17",'Phase 04 OPD Journey'!$G$2:$G$261,"BLOCKED")>0,"IN PROGRESS","NOT STARTED")))
A33: P4-S18 | B33: Phase 04 OPD Journey | C33: =COUNTIF('Phase 04 OPD Journey'!$O$2:$O$261,"P4-S18") | D33: =COUNTIFS('Phase 04 OPD Journey'!$O$2:$O$261,"P4-S18",'Phase 04 OPD Journey'!$G$2:$G$261,"PASS") | E33: =COUNTIFS('Phase 04 OPD Journey'!$O$2:$O$261,"P4-S18",'Phase 04 OPD Journey'!$G$2:$G$261,"FAIL") | F33: =COUNTIF('Phase 04 OPD Journey'!$O$2:$O$261,"P4-S18")-COUNTIFS('Phase 04 OPD Journey'!$O$2:$O$261,"P4-S18",'Phase 04 OPD Journey'!$G$2:$G$261,"PASS")-COUNTIFS('Phase 04 OPD Journey'!$O$2:$O$261,"P4-S18",'Phase 04 OPD Journey'!$G$2:$G$261,"FAIL")-COUNTIFS('Phase 04 OPD Journey'!$O$2:$O$261,"P4-S18",'Phase 04 OPD Journey'!$G$2:$G$261,"BLOCKED") | G33: =IF(COUNTIFS('Phase 04 OPD Journey'!$O$2:$O$261,"P4-S18",'Phase 04 OPD Journey'!$G$2:$G$261,"FAIL")>0,"FAIL",IF(COUNTIFS('Phase 04 OPD Journey'!$O$2:$O$261,"P4-S18",'Phase 04 OPD Journey'!$G$2:$G$261,"PASS")=COUNTIF('Phase 04 OPD Journey'!$O$2:$O$261,"P4-S18"),"PASS",IF(COUNTIFS('Phase 04 OPD Journey'!$O$2:$O$261,"P4-S18",'Phase 04 OPD Journey'!$G$2:$G$261,"PASS")+COUNTIFS('Phase 04 OPD Journey'!$O$2:$O$261,"P4-S18",'Phase 04 OPD Journey'!$G$2:$G$261,"BLOCKED")>0,"IN PROGRESS","NOT STARTED")))
A34: P4-S19 | B34: Phase 04 OPD Journey | C34: =COUNTIF('Phase 04 OPD Journey'!$O$2:$O$261,"P4-S19") | D34: =COUNTIFS('Phase 04 OPD Journey'!$O$2:$O$261,"P4-S19",'Phase 04 OPD Journey'!$G$2:$G$261,"PASS") | E34: =COUNTIFS('Phase 04 OPD Journey'!$O$2:$O$261,"P4-S19",'Phase 04 OPD Journey'!$G$2:$G$261,"FAIL") | F34: =COUNTIF('Phase 04 OPD Journey'!$O$2:$O$261,"P4-S19")-COUNTIFS('Phase 04 OPD Journey'!$O$2:$O$261,"P4-S19",'Phase 04 OPD Journey'!$G$2:$G$261,"PASS")-COUNTIFS('Phase 04 OPD Journey'!$O$2:$O$261,"P4-S19",'Phase 04 OPD Journey'!$G$2:$G$261,"FAIL")-COUNTIFS('Phase 04 OPD Journey'!$O$2:$O$261,"P4-S19",'Phase 04 OPD Journey'!$G$2:$G$261,"BLOCKED") | G34: =IF(COUNTIFS('Phase 04 OPD Journey'!$O$2:$O$261,"P4-S19",'Phase 04 OPD Journey'!$G$2:$G$261,"FAIL")>0,"FAIL",IF(COUNTIFS('Phase 04 OPD Journey'!$O$2:$O$261,"P4-S19",'Phase 04 OPD Journey'!$G$2:$G$261,"PASS")=COUNTIF('Phase 04 OPD Journey'!$O$2:$O$261,"P4-S19"),"PASS",IF(COUNTIFS('Phase 04 OPD Journey'!$O$2:$O$261,"P4-S19",'Phase 04 OPD Journey'!$G$2:$G$261,"PASS")+COUNTIFS('Phase 04 OPD Journey'!$O$2:$O$261,"P4-S19",'Phase 04 OPD Journey'!$G$2:$G$261,"BLOCKED")>0,"IN PROGRESS","NOT STARTED")))
A35: P4-S20 | B35: Phase 04 OPD Journey | C35: =COUNTIF('Phase 04 OPD Journey'!$O$2:$O$261,"P4-S20") | D35: =COUNTIFS('Phase 04 OPD Journey'!$O$2:$O$261,"P4-S20",'Phase 04 OPD Journey'!$G$2:$G$261,"PASS") | E35: =COUNTIFS('Phase 04 OPD Journey'!$O$2:$O$261,"P4-S20",'Phase 04 OPD Journey'!$G$2:$G$261,"FAIL") | F35: =COUNTIF('Phase 04 OPD Journey'!$O$2:$O$261,"P4-S20")-COUNTIFS('Phase 04 OPD Journey'!$O$2:$O$261,"P4-S20",'Phase 04 OPD Journey'!$G$2:$G$261,"PASS")-COUNTIFS('Phase 04 OPD Journey'!$O$2:$O$261,"P4-S20",'Phase 04 OPD Journey'!$G$2:$G$261,"FAIL")-COUNTIFS('Phase 04 OPD Journey'!$O$2:$O$261,"P4-S20",'Phase 04 OPD Journey'!$G$2:$G$261,"BLOCKED") | G35: =IF(COUNTIFS('Phase 04 OPD Journey'!$O$2:$O$261,"P4-S20",'Phase 04 OPD Journey'!$G$2:$G$261,"FAIL")>0,"FAIL",IF(COUNTIFS('Phase 04 OPD Journey'!$O$2:$O$261,"P4-S20",'Phase 04 OPD Journey'!$G$2:$G$261,"PASS")=COUNTIF('Phase 04 OPD Journey'!$O$2:$O$261,"P4-S20"),"PASS",IF(COUNTIFS('Phase 04 OPD Journey'!$O$2:$O$261,"P4-S20",'Phase 04 OPD Journey'!$G$2:$G$261,"PASS")+COUNTIFS('Phase 04 OPD Journey'!$O$2:$O$261,"P4-S20",'Phase 04 OPD Journey'!$G$2:$G$261,"BLOCKED")>0,"IN PROGRESS","NOT STARTED")))
A36: P4-S21 | B36: Phase 04 OPD Journey | C36: =COUNTIF('Phase 04 OPD Journey'!$O$2:$O$261,"P4-S21") | D36: =COUNTIFS('Phase 04 OPD Journey'!$O$2:$O$261,"P4-S21",'Phase 04 OPD Journey'!$G$2:$G$261,"PASS") | E36: =COUNTIFS('Phase 04 OPD Journey'!$O$2:$O$261,"P4-S21",'Phase 04 OPD Journey'!$G$2:$G$261,"FAIL") | F36: =COUNTIF('Phase 04 OPD Journey'!$O$2:$O$261,"P4-S21")-COUNTIFS('Phase 04 OPD Journey'!$O$2:$O$261,"P4-S21",'Phase 04 OPD Journey'!$G$2:$G$261,"PASS")-COUNTIFS('Phase 04 OPD Journey'!$O$2:$O$261,"P4-S21",'Phase 04 OPD Journey'!$G$2:$G$261,"FAIL")-COUNTIFS('Phase 04 OPD Journey'!$O$2:$O$261,"P4-S21",'Phase 04 OPD Journey'!$G$2:$G$261,"BLOCKED") | G36: =IF(COUNTIFS('Phase 04 OPD Journey'!$O$2:$O$261,"P4-S21",'Phase 04 OPD Journey'!$G$2:$G$261,"FAIL")>0,"FAIL",IF(COUNTIFS('Phase 04 OPD Journey'!$O$2:$O$261,"P4-S21",'Phase 04 OPD Journey'!$G$2:$G$261,"PASS")=COUNTIF('Phase 04 OPD Journey'!$O$2:$O$261,"P4-S21"),"PASS",IF(COUNTIFS('Phase 04 OPD Journey'!$O$2:$O$261,"P4-S21",'Phase 04 OPD Journey'!$G$2:$G$261,"PASS")+COUNTIFS('Phase 04 OPD Journey'!$O$2:$O$261,"P4-S21",'Phase 04 OPD Journey'!$G$2:$G$261,"BLOCKED")>0,"IN PROGRESS","NOT STARTED")))
A37: P4-S22 | B37: Phase 04 OPD Journey | C37: =COUNTIF('Phase 04 OPD Journey'!$O$2:$O$261,"P4-S22") | D37: =COUNTIFS('Phase 04 OPD Journey'!$O$2:$O$261,"P4-S22",'Phase 04 OPD Journey'!$G$2:$G$261,"PASS") | E37: =COUNTIFS('Phase 04 OPD Journey'!$O$2:$O$261,"P4-S22",'Phase 04 OPD Journey'!$G$2:$G$261,"FAIL") | F37: =COUNTIF('Phase 04 OPD Journey'!$O$2:$O$261,"P4-S22")-COUNTIFS('Phase 04 OPD Journey'!$O$2:$O$261,"P4-S22",'Phase 04 OPD Journey'!$G$2:$G$261,"PASS")-COUNTIFS('Phase 04 OPD Journey'!$O$2:$O$261,"P4-S22",'Phase 04 OPD Journey'!$G$2:$G$261,"FAIL")-COUNTIFS('Phase 04 OPD Journey'!$O$2:$O$261,"P4-S22",'Phase 04 OPD Journey'!$G$2:$G$261,"BLOCKED") | G37: =IF(COUNTIFS('Phase 04 OPD Journey'!$O$2:$O$261,"P4-S22",'Phase 04 OPD Journey'!$G$2:$G$261,"FAIL")>0,"FAIL",IF(COUNTIFS('Phase 04 OPD Journey'!$O$2:$O$261,"P4-S22",'Phase 04 OPD Journey'!$G$2:$G$261,"PASS")=COUNTIF('Phase 04 OPD Journey'!$O$2:$O$261,"P4-S22"),"PASS",IF(COUNTIFS('Phase 04 OPD Journey'!$O$2:$O$261,"P4-S22",'Phase 04 OPD Journey'!$G$2:$G$261,"PASS")+COUNTIFS('Phase 04 OPD Journey'!$O$2:$O$261,"P4-S22",'Phase 04 OPD Journey'!$G$2:$G$261,"BLOCKED")>0,"IN PROGRESS","NOT STARTED")))
A38: P4-S23 | B38: Phase 04 OPD Journey | C38: =COUNTIF('Phase 04 OPD Journey'!$O$2:$O$261,"P4-S23") | D38: =COUNTIFS('Phase 04 OPD Journey'!$O$2:$O$261,"P4-S23",'Phase 04 OPD Journey'!$G$2:$G$261,"PASS") | E38: =COUNTIFS('Phase 04 OPD Journey'!$O$2:$O$261,"P4-S23",'Phase 04 OPD Journey'!$G$2:$G$261,"FAIL") | F38: =COUNTIF('Phase 04 OPD Journey'!$O$2:$O$261,"P4-S23")-COUNTIFS('Phase 04 OPD Journey'!$O$2:$O$261,"P4-S23",'Phase 04 OPD Journey'!$G$2:$G$261,"PASS")-COUNTIFS('Phase 04 OPD Journey'!$O$2:$O$261,"P4-S23",'Phase 04 OPD Journey'!$G$2:$G$261,"FAIL")-COUNTIFS('Phase 04 OPD Journey'!$O$2:$O$261,"P4-S23",'Phase 04 OPD Journey'!$G$2:$G$261,"BLOCKED") | G38: =IF(COUNTIFS('Phase 04 OPD Journey'!$O$2:$O$261,"P4-S23",'Phase 04 OPD Journey'!$G$2:$G$261,"FAIL")>0,"FAIL",IF(COUNTIFS('Phase 04 OPD Journey'!$O$2:$O$261,"P4-S23",'Phase 04 OPD Journey'!$G$2:$G$261,"PASS")=COUNTIF('Phase 04 OPD Journey'!$O$2:$O$261,"P4-S23"),"PASS",IF(COUNTIFS('Phase 04 OPD Journey'!$O$2:$O$261,"P4-S23",'Phase 04 OPD Journey'!$G$2:$G$261,"PASS")+COUNTIFS('Phase 04 OPD Journey'!$O$2:$O$261,"P4-S23",'Phase 04 OPD Journey'!$G$2:$G$261,"BLOCKED")>0,"IN PROGRESS","NOT STARTED")))
A39: P4-S24 | B39: Phase 04 OPD Journey | C39: =COUNTIF('Phase 04 OPD Journey'!$O$2:$O$261,"P4-S24") | D39: =COUNTIFS('Phase 04 OPD Journey'!$O$2:$O$261,"P4-S24",'Phase 04 OPD Journey'!$G$2:$G$261,"PASS") | E39: =COUNTIFS('Phase 04 OPD Journey'!$O$2:$O$261,"P4-S24",'Phase 04 OPD Journey'!$G$2:$G$261,"FAIL") | F39: =COUNTIF('Phase 04 OPD Journey'!$O$2:$O$261,"P4-S24")-COUNTIFS('Phase 04 OPD Journey'!$O$2:$O$261,"P4-S24",'Phase 04 OPD Journey'!$G$2:$G$261,"PASS")-COUNTIFS('Phase 04 OPD Journey'!$O$2:$O$261,"P4-S24",'Phase 04 OPD Journey'!$G$2:$G$261,"FAIL")-COUNTIFS('Phase 04 OPD Journey'!$O$2:$O$261,"P4-S24",'Phase 04 OPD Journey'!$G$2:$G$261,"BLOCKED") | G39: =IF(COUNTIFS('Phase 04 OPD Journey'!$O$2:$O$261,"P4-S24",'Phase 04 OPD Journey'!$G$2:$G$261,"FAIL")>0,"FAIL",IF(COUNTIFS('Phase 04 OPD Journey'!$O$2:$O$261,"P4-S24",'Phase 04 OPD Journey'!$G$2:$G$261,"PASS")=COUNTIF('Phase 04 OPD Journey'!$O$2:$O$261,"P4-S24"),"PASS",IF(COUNTIFS('Phase 04 OPD Journey'!$O$2:$O$261,"P4-S24",'Phase 04 OPD Journey'!$G$2:$G$261,"PASS")+COUNTIFS('Phase 04 OPD Journey'!$O$2:$O$261,"P4-S24",'Phase 04 OPD Journey'!$G$2:$G$261,"BLOCKED")>0,"IN PROGRESS","NOT STARTED")))
A40: P5-S01 | B40: Phase 05 Lab & Radiology | C40: =COUNTIF('Phase 05 Lab & Radiology'!$O$2:$O$25,"P5-S01") | D40: =COUNTIFS('Phase 05 Lab & Radiology'!$O$2:$O$25,"P5-S01",'Phase 05 Lab & Radiology'!$G$2:$G$25,"PASS") | E40: =COUNTIFS('Phase 05 Lab & Radiology'!$O$2:$O$25,"P5-S01",'Phase 05 Lab & Radiology'!$G$2:$G$25,"FAIL") | F40: =COUNTIF('Phase 05 Lab & Radiology'!$O$2:$O$25,"P5-S01")-COUNTIFS('Phase 05 Lab & Radiology'!$O$2:$O$25,"P5-S01",'Phase 05 Lab & Radiology'!$G$2:$G$25,"PASS")-COUNTIFS('Phase 05 Lab & Radiology'!$O$2:$O$25,"P5-S01",'Phase 05 Lab & Radiology'!$G$2:$G$25,"FAIL")-COUNTIFS('Phase 05 Lab & Radiology'!$O$2:$O$25,"P5-S01",'Phase 05 Lab & Radiology'!$G$2:$G$25,"BLOCKED") | G40: =IF(COUNTIFS('Phase 05 Lab & Radiology'!$O$2:$O$25,"P5-S01",'Phase 05 Lab & Radiology'!$G$2:$G$25,"FAIL")>0,"FAIL",IF(COUNTIFS('Phase 05 Lab & Radiology'!$O$2:$O$25,"P5-S01",'Phase 05 Lab & Radiology'!$G$2:$G$25,"PASS")=COUNTIF('Phase 05 Lab & Radiology'!$O$2:$O$25,"P5-S01"),"PASS",IF(COUNTIFS('Phase 05 Lab & Radiology'!$O$2:$O$25,"P5-S01",'Phase 05 Lab & Radiology'!$G$2:$G$25,"PASS")+COUNTIFS('Phase 05 Lab & Radiology'!$O$2:$O$25,"P5-S01",'Phase 05 Lab & Radiology'!$G$2:$G$25,"BLOCKED")>0,"IN PROGRESS","NOT STARTED")))
...

Sheet Go-Live Readiness
A1: Category | B1: Scenario | C1: What must be true | D1: Status | E1: Evidence / Notes
A2: Patient safety | B2: P4-S11 | C2: Drug allergy prescription is blocked; override is audited
A3: Patient safety | B3: P4-S10 | C3: Drug interaction alert fires
A4: Patient safety | B4: P5-S07 | C4: Critical lab value raises an immediate alert
A5: Patient safety | B5: P5-S06 | C5: Rejected sample re-queues without double-charging
A6: Patient safety | B6: P5-S10 | C6: Dual-validation test cannot be released by one person
A7: Patient safety | B7: P6-S04 | C7: FEFO batch selection picks the earliest expiry
A8: Patient safety | B8: P6-S05 | C8: Expired batch cannot be dispensed
A9: Patient safety | B9: P6-S07 | C9: NDPS dispensing requires dual sign-off
A10: Patient safety | B10: P6-S08 | C10: NDPS with a single signature is blocked
A11: Patient safety | B11: P7-S06 | C11: ICU flowsheet, ventilator and sedation records save
A12: Patient safety | B12: P10-OT | C12: WHO surgical checklist cannot be bypassed
A13: Patient safety | B13: P10-BB | C13: Blood cross-match is traceable donor to recipient
... A56: Regression | B56: R7 | C56: Cross-tenant sweep
A58: VERDICT | C58: All must-pass items green AND zero open P1 defects anywhere | D58: =IF(COUNTIF(D2:D56,"PASS")=55,"READY TO GO LIVE","NOT READY")

Sheet Phase 01 Foundation & Access
A1: TC# | B1: Section | C1: Priority | D1: Test Case | E1: Steps | F1: Expected Result | G1: Status(PASS/FAIL/BLOCKED) | H1: mock data | I1: Cross-Module Link | J1: Settings need to set before entering to the module | K1: Actual Result(What happened) | L1: Console Error(Copy-paste red text) | M1: Screenshot(Y/N) | N1: Notes | O1: Journey Scenario | P1: Why This Exists | Q1: Test Type | R1: Role/Login | S1: Supabase Verify | T1: Playwright Spec | U1: Defect ID | V1: Stages Passed / Total
A2: TC-P1A-001 | B2: 1A Registration | C2: P2 | D2: Registration page loads with step 1 of 5 | E2: 1) Open /register in a fresh incognito window 2) Observe the wizard | F2: Step 1 'Hospital Identity' renders with a 5-step progress bar. No console errors. | G2: Pass | H2: None | J2: None - public route | O2: P1-Setup | P2: A hospital cannot become a customer if it cannot sign up. This is the very first screen anyone outside your company ever sees. | Q2: Positive | R2: Logged out | S2: None | T2: e2e/phase-01-foundation/P1A.registration.spec.ts
